
public class java158
{
   public static void main (String args[])
   {
	  throw new ArithmeticException("Division by Zero");
	  System.out.println("Result");  //Question arrises that why here the line an error
	  //because in above the throw keyword say that "Division by Zero" means exception is already in above line
	  //So according to exception rule the below line is not execute in the of Exception.
   }
}
